Workbook

Sheet Dashboard
A1: CONTROL UV DTF — RENDIMIENTO DEL ROLLO A
A3: Indicador principal | B3: Valor
A4: Rollo A actualmente en uso | B4: ='Control de rollos'!B2 -> A-001
A5: Fecha de inicio | B5: ='Control de rollos'!C2 -> 46272
A6: Metros iniciales | B6: ='Control de rollos'!E2 -> 100
A7: Metros impresos | B7: ='Control de rollos'!F2 -> 36.117
A8: Metros restantes | B8: ='Control de rollos'!G2 -> 63.883
A9: Trabajos registrados | B9: ='Control de rollos'!K2 -> 61
A10: Total cobrado por ese rollo A | B10: =SUM('Registro de trabajos'!H:H) -> 2777.2
A11: Ingreso promedio por metro impreso | B11: =IFERROR(B10/(SUM('Registro de trabajos'!E:E)+SUM('Registro de trabajos'!G:G)),0) -> 38.512314
A12: Nota: | B12: El cobro corresponde al trabajo completo A+B y se suma una sola vez.
A14: HISTORIAL DE ROLLOS A Y B
A15: Tipo | B15: ID del rollo | C15: Fecha inicio | D15: Fecha término | E15: Metros iniciales | F15: Metros impresos | G15: Metros restantes | H15: Trabajos | I15: Estado | J15: Total cobrado
A16: ='Control de rollos'!A2 -> A | B16: ='Control de rollos'!B2 -> A-001 | C16: ='Control de rollos'!C2 -> 46272 | D16: =IF('Control de rollos'!D2="","",'Control de rollos'!D2) | E16: ='Control de rollos'!E2 -> 100 | F16: =SUMIF('Registro de trabajos'!D:D,B16,'Registro de trabajos'!E:E) -> 36.117 | G16: =MAX(0,E16-F16) -> 63.883 | H16: =COUNTIF('Registro de trabajos'!D:D,B16) -> 61 | I16: ='Control de rollos'!M2 -> EN USO | J16: =IF('Control de rollos'!B2="","",'Control de rollos'!H2) -> 2777.2
A17: ='Control de rollos'!A3 -> B | B17: ='Control de rollos'!B3 -> B-001 | C17: ='Control de rollos'!C3 -> 46241 | D17: ='Control de rollos'!D3 -> 46273 | E17: ='Control de rollos'!E3 -> 100 | F17: =SUMIF('Registro de trabajos'!F:F,B17,'Registro de trabajos'!G:G) -> 5.115 | G17: =MAX(0,E17-F17) -> 94.885 | H17: =COUNTIF('Registro de trabajos'!F:F,B17) -> 6 | I17: ='Control de rollos'!M3 -> FINALIZADO | J17: =IF('Control de rollos'!B3="","",'Control de rollos'!H3) -> 0
A18: ='Control de rollos'!A4 -> B | B18: ='Control de rollos'!B4 -> B-002 | C18: ='Control de rollos'!C4 -> 46273 | D18: =IF('Control de rollos'!D4="","",'Control de rollos'!D4) | E18: ='Control de rollos'!E4 -> 100 | F18: =SUMIF('Registro de trabajos'!F:F,B18,'Registro de trabajos'!G:G) -> 30.88 | G18: =MAX(0,E18-F18) -> 69.12 | H18: =COUNTIF('Registro de trabajos'!F:F,B18) -> 55 | I18: ='Control de rollos'!M4 -> EN USO | J18: =IF('Control de rollos'!B4="","",'Control de rollos'!H4) -> 0

Sheet Registro de trabajos
A1: REGISTRO DE TRABAJOS UV DTF
A2: Una fila = un trabajo. Registra los metros A y B, pero el cobro se coloca UNA SOLA VEZ porque corresponde al trabajo completo A+B.
A3: Fecha | B3: N° de trabajo | C3: Cliente / Descripción | D3: Rollo A | E3: Metros impresos (m) | F3: Rollo B | G3: Metros B (m) | H3: Cobrado (A+B) | I3: Medio de pago | J3: Observaciones
A4: 46273 | B4: 1 | C4: 951 112 094 | D4: A-001 | E4: 1.5 | F4: B-001 | G4: 1.5 | H4: 95 | I4: Yapeo | J4: PLANCHA Y MEDIA
A5: 46272 | B5: 2 | C5: 949 337 517 | D5: A-001 | E5: 1.8 | F5: B-001 | G5: 1.8 | H5: 108 | I5: Yapeo | J5: 1 METRO + 80 CM
A6: 46272 | B6: 3 | C6: STEWART | D6: A-001 | E6: 0.105 | F6: B-001 | G6: 0.105 | H6: 15 | I6: Yapeo | J6: A4
A7: 46273 | B7: 4 | C7: edymil | D7: A-001 | E7: 0.21 | F7: B-002 | G7: 0.21 | H7: 25 | I7: Yapeo | J7: A3
A8: 46273 | B8: 5 | C8: JUAN VERGARA | D8: A-001 | E8: 0.5 | F8: B-001 | G8: 0.5 | H8: 40 | I8: Yapeo | J8: 1/2 Plancha
A9: 46273 | B9: 6 | C9: MIGUEL | D9: A-001 | E9: 1 | F9: B-001 | G9: 1 | H9: 70 | I9: Yapeo | J9: 1 PLANCHA
A10: 46273 | B10: 7 | C10: JACK PRINT | D10: A-001 | E10: 1 | F10: B-002 | G10: 1 | H10: 60 | I10: Yapeo | J10: 1 PLANCHA
A11: 46273 | B11: 8 | C11: gigantografias uv | D11: A-001 | E11: 1 | F11: B-002 | G11: 1 | H11: 60 | I11: Yapeo | J11: 1 PLANCHA
A12: 46274 | B12: 9 | C12: FUTURO | D12: A-001 | E12: 0.3 | F12: B-002 | G12: 0.3 | H12: 30 | I12: Yapeo | J12: A3+
A13: 46274 | B13: 10 | C13: SUPER ART ESTUDIO | D13: A-001 | E13: 0.21 | F13: B-002 | G13: 0.21 | H13: 25 | I13: Yapeo | J13: A3
A14: 46274 | B14: 11 | C14: DINCA | D14: A-001 | E14: 0.8 | F14: B-002 | G14: 0.8 | H14: 50 | I14: Yapeo | J14: 1/2 plancha +
A15: 46274 | B15: 12 | C15: MAYOGA | D15: A-001 | E15: 1 | F15: B-002 | G15: 1 | H15: 60 | I15: Yapeo | J15: 1 PLANCHA
... A51: 46282 | B51: 45 | C51: TALENTUS | D51: A-001 | E51: 0.5 | F51: B-002 | G51: 0.5 | H51: 40 | I51: Yapeo | J51: 1/2 PLANCHA
A52: 46282 | B52: 46 | C52: CARLOS | D52: A-001 | E52: 0.11 | F52: B-002 | G52: 0.11 | I52: Yapeo | J52: A4
A53: 46282 | B53: 47 | C53: FREPAP | D53: A-001 | E53: 2.5 | F53: B-002 | G53: 2.5 | H53: 180 | I53: Yapeo | J53: 2 PLANCHAS Y MEDIA
A54: 46282 | B54: 48 | C54: AUTONORT | D54: A-001 | E54: 0.1 | F54: B-002 | G54: 0.1 | H54: 10 | I54: Yapeo | J54: A4+
A55: 46282 | B55: 49 | C55: MAYOGA | D55: A-001 | E55: 0.15 | F55: B-002 | G55: 0.11 | H55: 15 | I55: Yapeo | J55: A4
A56: 46282 | B56: 50 | C56: MAYOGA | D56: A-001 | E56: 0.15 | F56: B-002 | G56: 0.11 | H56: 15 | I56: Yapeo | J56: A4
A57: 46283 | B57: 51 | C57: GRAFICA FUTURO | D57: A-001 | E57: 0.11 | F57: B-002 | G57: 0.11 | H57: 15 | I57: Yapeo | J57: A4
A58: 46283 | B58: 52 | C58: MUG | D58: A-001 | E58: 0.11 | F58: B-002 | G58: 0.11 | H58: 39 | I58: Yapeo | J58: A4
A59: 46283 | B59: 53 | C59: FUSION CLIENTES | D59: A-001 | E59: 0.11 | F59: B-002 | G59: 0.11 | H59: 25 | I59: Yapeo | J59: A4
A60: 46283 | B60: 54 | C60: CLIENTE | D60: A-001 | E60: 0.11 | F60: B-002 | G60: 0.11 | H60: 15 | I60: Yapeo | J60: A4
A61: 46283 | B61: 55 | C61: BARRO | D61: A-001 | E61: 0.11 | F61: B-002 | G61: 0.11 | H61: 20 | I61: Yapeo | J61: A4
A62: 46283 | B62: 56 | C62: JUNIOR CODEX | D62: A-001 | E62: 0.5 | F62: B-002 | G62: 0.5 | H62: 40 | I62: Efectivo | J62: 1/2 PLANCHA
A63: 46283 | B63: 57 | C63: MAYOGA | D63: A-001 | E63: 0.11 | F63: B-002 | G63: 0.11 | H63: 15 | I63: Yapeo | J63: A4
A64: 46283 | B64: 58 | C64: AUTONORT CLIENTE 2 | D64: A-001 | E64: 0.11 | F64: B-002 | G64: 0.11 | H64: 20 | I64: Efectivo | J64: A4

Sheet Control de rollos
A1: Tipo | B1: ID del rollo | C1: Fecha inicio | D1: Fecha término | E1: Metros iniciales | F1: Metros impresos | G1: Metros restantes | H1: Total cobrado | I1: Costo | J1: Ganancia estimada | K1: Trabajos | L1: Metros B usados | M1: Estado
A2: A | B2: =IF(A2="","",A2&"-"&TEXT(COUNTIF($A$2:A2,A2),"000")) -> A-001 | C2: 46272 | E2: =Configuración!B3 -> 100 | F2: =SUMIF('Registro de trabajos'!D:D,B2,'Registro de trabajos'!E:E) -> 36.117 | G2: =MAX(0,E2-F2) -> 63.883 | H2: =SUMIF('Registro de trabajos'!D:D,B2,'Registro de trabajos'!H:H) -> 2777.2 | I2: =Configuración!B4 -> 0 | J2: =H2-I2 -> 2777.2 | K2: =COUNTIF('Registro de trabajos'!D:D,B2) -> 61 | L2: =SUMIF('Registro de trabajos'!D:D,B2,'Registro de trabajos'!G:G) -> 35.995 | M2: EN USO
A3: B | B3: =IF(A3="","",A3&"-"&TEXT(COUNTIF($A$2:A3,A3),"000")) -> B-001 | C3: 46241 | D3: 46273 | E3: 100 | F3: =SUMIF('Registro de trabajos'!F:F,B3,'Registro de trabajos'!G:G) -> 5.115 | G3: =MAX(0,E3-F3) -> 94.885 | H3: 0 | I3: 0 | J3: 0 | K3: =COUNTIF('Registro de trabajos'!F:F,B3) -> 6 | L3: =F3 -> 5.115 | M3: FINALIZADO
A4: B | B4: =IF(A4="","",A4&"-"&TEXT(COUNTIF($A$2:A4,A4),"000")) -> B-002 | C4: 46273 | E4: =Configuración!B3 -> 100 | F4: =SUMIF('Registro de trabajos'!F:F,B4,'Registro de trabajos'!G:G) -> 30.88 | G4: =MAX(0,E4-F4) -> 69.12 | H4: 0 | I4: 0 | J4: 0 | K4: =COUNTIF('Registro de trabajos'!F:F,B4) -> 55 | L4: =F4 -> 30.88 | M4: EN USO
A5: =IF('Control de rollos'!D2<>"","A","") | B5: =IF(A5="","",A5&"-"&TEXT(COUNTIF($A$2:A5,A5),"000")) | C5: =IF(A5="","",D2) | E5: =IF(A5="","",Configuración!B3) | F5: =IF(A5="","",SUMIF('Registro de trabajos'!D:D,B5,'Registro de trabajos'!E:E)) | G5: =IF(A5="","",MAX(0,E5-F5)) | H5: =IF(A5="","",SUMIF('Registro de trabajos'!D:D,B5,'Registro de trabajos'!H:H)) | I5: =IF(A5="","",Configuración!B4) | J5: =IF(A5="","",H5-I5) | K5: =IF(A5="","",COUNTIF('Registro de trabajos'!D:D,B5)) | L5: =IF(A5="","",SUMIF('Registro de trabajos'!D:D,B5,'Registro de trabajos'!G:G)) | M5: =IF(A5="","",IF(D5="","EN USO","FINALIZADO"))
A6: =IF('Control de rollos'!D4<>"","B","") | B6: =IF(A6="","",A6&"-"&TEXT(COUNTIF($A$2:A6,A6),"000")) | C6: =IF(A6="","",D4) | E6: =IF(A6="","",Configuración!B3) | F6: =IF(A6="","",SUMIF('Registro de trabajos'!F:F,B6,'Registro de trabajos'!G:G)) | G6: =IF(A6="","",MAX(0,E6-F6)) | H6: =IF(A6="","",0) | I6: =IF(A6="","",0) | J6: =IF(A6="","",H6-I6) | K6: =IF(A6="","",COUNTIF('Registro de trabajos'!F:F,B6)) | L6: =IF(A6="","",F6) | M6: =IF(A6="","",IF(D6="","EN USO","FINALIZADO"))
A7: =IF('Control de rollos'!D4<>"","A","") | B7: =IF(A7="","",A7&"-"&TEXT(COUNTIF($A$2:A7,A7),"000")) | C7: =IF(A7="","",D4) | E7: =IF(A7="","",Configuración!B3) | F7: =IF(A7="","",SUMIF('Registro de trabajos'!D:D,B7,'Registro de trabajos'!E:E)) | G7: =IF(A7="","",MAX(0,E7-F7)) | H7: =IF(A7="","",SUMIF('Registro de trabajos'!D:D,B7,'Registro de trabajos'!H:H)) | I7: =IF(A7="","",Configuración!B4) | J7: =IF(A7="","",H7-I7) | K7: =IF(A7="","",COUNTIF('Registro de trabajos'!D:D,B7)) | L7: =IF(A7="","",SUMIF('Registro de trabajos'!D:D,B7,'Registro de trabajos'!G:G)) | M7: =IF(A7="","",IF(D7="","EN USO","FINALIZADO"))
A8: =IF('Control de rollos'!D6<>"","B","") | B8: =IF(A8="","",A8&"-"&TEXT(COUNTIF($A$2:A8,A8),"000")) | C8: =IF(A8="","",D6) | E8: =IF(A8="","",Configuración!B3) | F8: =IF(A8="","",SUMIF('Registro de trabajos'!F:F,B8,'Registro de trabajos'!G:G)) | G8: =IF(A8="","",MAX(0,E8-F8)) | H8: =IF(A8="","",0) | I8: =IF(A8="","",0) | J8: =IF(A8="","",H8-I8) | K8: =IF(A8="","",COUNTIF('Registro de trabajos'!F:F,B8)) | L8: =IF(A8="","",F8) | M8: =IF(A8="","",IF(D8="","EN USO","FINALIZADO"))
A9: =IF('Control de rollos'!D6<>"","A","") | B9: =IF(A9="","",A9&"-"&TEXT(COUNTIF($A$2:A9,A9),"000")) | C9: =IF(A9="","",D6) | E9: =IF(A9="","",Configuración!B3) | F9: =IF(A9="","",SUMIF('Registro de trabajos'!D:D,B9,'Registro de trabajos'!E:E)) | G9: =IF(A9="","",MAX(0,E9-F9)) | H9: =IF(A9="","",SUMIF('Registro de trabajos'!D:D,B9,'Registro de trabajos'!H:H)) | I9: =IF(A9="","",Configuración!B4) | J9: =IF(A9="","",H9-I9) | K9: =IF(A9="","",COUNTIF('Registro de trabajos'!D:D,B9)) | L9: =IF(A9="","",SUMIF('Registro de trabajos'!D:D,B9,'Registro de trabajos'!G:G)) | M9: =IF(A9="","",IF(D9="","EN USO","FINALIZADO"))
A10: =IF('Control de rollos'!D8<>"","B","") | B10: =IF(A10="","",A10&"-"&TEXT(COUNTIF($A$2:A10,A10),"000")) | C10: =IF(A10="","",D8) | E10: =IF(A10="","",Configuración!B3) | F10: =IF(A10="","",SUMIF('Registro de trabajos'!F:F,B10,'Registro de trabajos'!G:G)) | G10: =IF(A10="","",MAX(0,E10-F10)) | H10: =IF(A10="","",0) | I10: =IF(A10="","",0) | J10: =IF(A10="","",H10-I10) | K10: =IF(A10="","",COUNTIF('Registro de trabajos'!F:F,B10)) | L10: =IF(A10="","",F10) | M10: =IF(A10="","",IF(D10="","EN USO","FINALIZADO"))
A11: =IF('Control de rollos'!D8<>"","A","") | B11: =IF(A11="","",A11&"-"&TEXT(COUNTIF($A$2:A11,A11),"000")) | C11: =IF(A11="","",D8) | E11: =IF(A11="","",Configuración!B3) | F11: =IF(A11="","",SUMIF('Registro de trabajos'!D:D,B11,'Registro de trabajos'!E:E)) | G11: =IF(A11="","",MAX(0,E11-F11)) | H11: =IF(A11="","",SUMIF('Registro de trabajos'!D:D,B11,'Registro de trabajos'!H:H)) | I11: =IF(A11="","",Configuración!B4) | J11: =IF(A11="","",H11-I11) | K11: =IF(A11="","",COUNTIF('Registro de trabajos'!D:D,B11)) | L11: =IF(A11="","",SUMIF('Registro de trabajos'!D:D,B11,'Registro de trabajos'!G:G)) | M11: =IF(A11="","",IF(D11="","EN USO","FINALIZADO"))
A12: =IF('Control de rollos'!D10<>"","B","") | B12: =IF(A12="","",A12&"-"&TEXT(COUNTIF($A$2:A12,A12),"000")) | C12: =IF(A12="","",D10) | E12: =IF(A12="","",Configuración!B3) | F12: =IF(A12="","",SUMIF('Registro de trabajos'!F:F,B12,'Registro de trabajos'!G:G)) | G12: =IF(A12="","",MAX(0,E12-F12)) | H12: =IF(A12="","",0) | I12: =IF(A12="","",0) | J12: =IF(A12="","",H12-I12) | K12: =IF(A12="","",COUNTIF('Registro de trabajos'!F:F,B12)) | L12: =IF(A12="","",F12) | M12: =IF(A12="","",IF(D12="","EN USO","FINALIZADO"))
A13: =IF('Control de rollos'!D10<>"","A","") | B13: =IF(A13="","",A13&"-"&TEXT(COUNTIF($A$2:A13,A13),"000")) | C13: =IF(A13="","",D10) | E13: =IF(A13="","",Configuración!B3) | F13: =IF(A13="","",SUMIF('Registro de trabajos'!D:D,B13,'Registro de trabajos'!E:E)) | G13: =IF(A13="","",MAX(0,E13-F13)) | H13: =IF(A13="","",SUMIF('Registro de trabajos'!D:D,B13,'Registro de trabajos'!H:H)) | I13: =IF(A13="","",Configuración!B4) | J13: =IF(A13="","",H13-I13) | K13: =IF(A13="","",COUNTIF('Registro de trabajos'!D:D,B13)) | L13: =IF(A13="","",SUMIF('Registro de trabajos'!D:D,B13,'Registro de trabajos'!G:G)) | M13: =IF(A13="","",IF(D13="","EN USO","FINALIZADO"))
A14: =IF('Control de rollos'!D12<>"","B","") | B14: =IF(A14="","",A14&"-"&TEXT(COUNTIF($A$2:A14,A14),"000")) | C14: =IF(A14="","",D12) | E14: =IF(A14="","",Configuración!B3) | F14: =IF(A14="","",SUMIF('Registro de trabajos'!F:F,B14,'Registro de trabajos'!G:G)) | G14: =IF(A14="","",MAX(0,E14-F14)) | H14: =IF(A14="","",0) | I14: =IF(A14="","",0) | J14: =IF(A14="","",H14-I14) | K14: =IF(A14="","",COUNTIF('Registro de trabajos'!F:F,B14)) | L14: =IF(A14="","",F14) | M14: =IF(A14="","",IF(D14="","EN USO","FINALIZADO"))
A15: =IF('Control de rollos'!D12<>"","A","") | B15: =IF(A15="","",A15&"-"&TEXT(COUNTIF($A$2:A15,A15),"000")) | C15: =IF(A15="","",D12) | E15: =IF(A15="","",Configuración!B3) | F15: =IF(A15="","",SUMIF('Registro de trabajos'!D:D,B15,'Registro de trabajos'!E:E)) | G15: =IF(A15="","",MAX(0,E15-F15)) | H15: =IF(A15="","",SUMIF('Registro de trabajos'!D:D,B15,'Registro de trabajos'!H:H)) | I15: =IF(A15="","",Configuración!B4) | J15: =IF(A15="","",H15-I15) | K15: =IF(A15="","",COUNTIF('Registro de trabajos'!D:D,B15)) | L15: =IF(A15="","",SUMIF('Registro de trabajos'!D:D,B15,'Registro de trabajos'!G:G)) | M15: =IF(A15="","",IF(D15="","EN USO","FINALIZADO"))
A16: =IF('Control de rollos'!D14<>"","B","") | B16: =IF(A16="","",A16&"-"&TEXT(COUNTIF($A$2:A16,A16),"000")) | C16: =IF(A16="","",D14) | E16: =IF(A16="","",Configuración!B3) | F16: =IF(A16="","",SUMIF('Registro de trabajos'!F:F,B16,'Registro de trabajos'!G:G)) | G16: =IF(A16="","",MAX(0,E16-F16)) | H16: =IF(A16="","",0) | I16: =IF(A16="","",0) | J16: =IF(A16="","",H16-I16) | K16: =IF(A16="","",COUNTIF('Registro de trabajos'!F:F,B16)) | L16: =IF(A16="","",F16) | M16: =IF(A16="","",IF(D16="","EN USO","FINALIZADO"))
A17: =IF('Control de rollos'!D14<>"","A","") | B17: =IF(A17="","",A17&"-"&TEXT(COUNTIF($A$2:A17,A17),"000")) | C17: =IF(A17="","",D14) | E17: =IF(A17="","",Configuración!B3) | F17: =IF(A17="","",SUMIF('Registro de trabajos'!D:D,B17,'Registro de trabajos'!E:E)) | G17: =IF(A17="","",MAX(0,E17-F17)) | H17: =IF(A17="","",SUMIF('Registro de trabajos'!D:D,B17,'Registro de trabajos'!H:H)) | I17: =IF(A17="","",Configuración!B4) | J17: =IF(A17="","",H17-I17) | K17: =IF(A17="","",COUNTIF('Registro de trabajos'!D:D,B17)) | L17: =IF(A17="","",SUMIF('Registro de trabajos'!D:D,B17,'Registro de trabajos'!G:G)) | M17: =IF(A17="","",IF(D17="","EN USO","FINALIZADO"))
A18: =IF('Control de rollos'!D16<>"","B","") | B18: =IF(A18="","",A18&"-"&TEXT(COUNTIF($A$2:A18,A18),"000")) | C18: =IF(A18="","",D16) | E18: =IF(A18="","",Configuración!B3) | F18: =IF(A18="","",SUMIF('Registro de trabajos'!F:F,B18,'Registro de trabajos'!G:G)) | G18: =IF(A18="","",MAX(0,E18-F18)) | H18: =IF(A18="","",0) | I18: =IF(A18="","",0) | J18: =IF(A18="","",H18-I18) | K18: =IF(A18="","",COUNTIF('Registro de trabajos'!F:F,B18)) | L18: =IF(A18="","",F18) | M18: =IF(A18="","",IF(D18="","EN USO","FINALIZADO"))
A19: =IF('Control de rollos'!D16<>"","A","") | B19: =IF(A19="","",A19&"-"&TEXT(COUNTIF($A$2:A19,A19),"000")) | C19: =IF(A19="","",D16) | E19: =IF(A19="","",Configuración!B3) | F19: =IF(A19="","",SUMIF('Registro de trabajos'!D:D,B19,'Registro de trabajos'!E:E)) | G19: =IF(A19="","",MAX(0,E19-F19)) | H19: =IF(A19="","",SUMIF('Registro de trabajos'!D:D,B19,'Registro de trabajos'!H:H)) | I19: =IF(A19="","",Configuración!B4) | J19: =IF(A19="","",H19-I19) | K19: =IF(A19="","",COUNTIF('Registro de trabajos'!D:D,B19)) | L19: =IF(A19="","",SUMIF('Registro de trabajos'!D:D,B19,'Registro de trabajos'!G:G)) | M19: =IF(A19="","",IF(D19="","EN USO","FINALIZADO"))
A20: =IF('Control de rollos'!D18<>"","B","") | B20: =IF(A20="","",A20&"-"&TEXT(COUNTIF($A$2:A20,A20),"000")) | C20: =IF(A20="","",D18) | E20: =IF(A20="","",Configuración!B3) | F20: =IF(A20="","",SUMIF('Registro de trabajos'!F:F,B20,'Registro de trabajos'!G:G)) | G20: =IF(A20="","",MAX(0,E20-F20)) | H20: =IF(A20="","",0) | I20: =IF(A20="","",0) | J20: =IF(A20="","",H20-I20) | K20: =IF(A20="","",COUNTIF('Registro de trabajos'!F:F,B20)) | L20: =IF(A20="","",F20) | M20: =IF(A20="","",IF(D20="","EN USO","FINALIZADO"))
A21: =IF('Control de rollos'!D18<>"","A","") | B21: =IF(A21="","",A21&"-"&TEXT(COUNTIF($A$2:A21,A21),"000")) | C21: =IF(A21="","",D18) | E21: =IF(A21="","",Configuración!B3) | F21: =IF(A21="","",SUMIF('Registro de trabajos'!D:D,B21,'Registro de trabajos'!E:E)) | G21: =IF(A21="","",MAX(0,E21-F21)) | H21: =IF(A21="","",SUMIF('Registro de trabajos'!D:D,B21,'Registro de trabajos'!H:H)) | I21: =IF(A21="","",Configuración!B4) | J21: =IF(A21="","",H21-I21) | K21: =IF(A21="","",COUNTIF('Registro de trabajos'!D:D,B21)) | L21: =IF(A21="","",SUMIF('Registro de trabajos'!D:D,B21,'Registro de trabajos'!G:G)) | M21: =IF(A21="","",IF(D21="","EN USO","FINALIZADO"))
A22: =IF('Control de rollos'!D20<>"","B","") | B22: =IF(A22="","",A22&"-"&TEXT(COUNTIF($A$2:A22,A22),"000")) | C22: =IF(A22="","",D20) | E22: =IF(A22="","",Configuración!B3) | F22: =IF(A22="","",SUMIF('Registro de trabajos'!F:F,B22,'Registro de trabajos'!G:G)) | G22: =IF(A22="","",MAX(0,E22-F22)) | H22: =IF(A22="","",0) | I22: =IF(A22="","",0) | J22: =IF(A22="","",H22-I22) | K22: =IF(A22="","",COUNTIF('Registro de trabajos'!F:F,B22)) | L22: =IF(A22="","",F22) | M22: =IF(A22="","",IF(D22="","EN USO","FINALIZADO"))
A23: =IF('Control de rollos'!D20<>"","A","") | B23: =IF(A23="","",A23&"-"&TEXT(COUNTIF($A$2:A23,A23),"000")) | C23: =IF(A23="","",D20) | E23: =IF(A23="","",Configuración!B3) | F23: =IF(A23="","",SUMIF('Registro de trabajos'!D:D,B23,'Registro de trabajos'!E:E)) | G23: =IF(A23="","",MAX(0,E23-F23)) | H23: =IF(A23="","",SUMIF('Registro de trabajos'!D:D,B23,'Registro de trabajos'!H:H)) | I23: =IF(A23="","",Configuración!B4) | J23: =IF(A23="","",H23-I23) | K23: =IF(A23="","",COUNTIF('Registro de trabajos'!D:D,B23)) | L23: =IF(A23="","",SUMIF('Registro de trabajos'!D:D,B23,'Registro de trabajos'!G:G)) | M23: =IF(A23="","",IF(D23="","EN USO","FINALIZADO"))
A24: =IF('Control de rollos'!D22<>"","B","") | B24: =IF(A24="","",A24&"-"&TEXT(COUNTIF($A$2:A24,A24),"000")) | C24: =IF(A24="","",D22) | E24: =IF(A24="","",Configuración!B3) | F24: =IF(A24="","",SUMIF('Registro de trabajos'!F:F,B24,'Registro de trabajos'!G:G)) | G24: =IF(A24="","",MAX(0,E24-F24)) | H24: =IF(A24="","",0) | I24: =IF(A24="","",0) | J24: =IF(A24="","",H24-I24) | K24: =IF(A24="","",COUNTIF('Registro de trabajos'!F:F,B24)) | L24: =IF(A24="","",F24) | M24: =IF(A24="","",IF(D24="","EN USO","FINALIZADO"))
A25: =IF('Control de rollos'!D22<>"","A","") | B25: =IF(A25="","",A25&"-"&TEXT(COUNTIF($A$2:A25,A25),"000")) | C25: =IF(A25="","",D22) | E25: =IF(A25="","",Configuración!B3) | F25: =IF(A25="","",SUMIF('Registro de trabajos'!D:D,B25,'Registro de trabajos'!E:E)) | G25: =IF(A25="","",MAX(0,E25-F25)) | H25: =IF(A25="","",SUMIF('Registro de trabajos'!D:D,B25,'Registro de trabajos'!H:H)) | I25: =IF(A25="","",Configuración!B4) | J25: =IF(A25="","",H25-I25) | K25: =IF(A25="","",COUNTIF('Registro de trabajos'!D:D,B25)) | L25: =IF(A25="","",SUMIF('Registro de trabajos'!D:D,B25,'Registro de trabajos'!G:G)) | M25: =IF(A25="","",IF(D25="","EN USO","FINALIZADO"))
A26: =IF('Control de rollos'!D24<>"","B","") | B26: =IF(A26="","",A26&"-"&TEXT(COUNTIF($A$2:A26,A26),"000")) | C26: =IF(A26="","",D24) | E26: =IF(A26="","",Configuración!B3) | F26: =IF(A26="","",SUMIF('Registro de trabajos'!F:F,B26,'Registro de trabajos'!G:G)) | G26: =IF(A26="","",MAX(0,E26-F26)) | H26: =IF(A26="","",0) | I26: =IF(A26="","",0) | J26: =IF(A26="","",H26-I26) | K26: =IF(A26="","",COUNTIF('Registro de trabajos'!F:F,B26)) | L26: =IF(A26="","",F26) | M26: =IF(A26="","",IF(D26="","EN USO","FINALIZADO"))
A27: =IF('Control de rollos'!D24<>"","A","") | B27: =IF(A27="","",A27&"-"&TEXT(COUNTIF($A$2:A27,A27),"000")) | C27: =IF(A27="","",D24) | E27: =IF(A27="","",Configuración!B3) | F27: =IF(A27="","",SUMIF('Registro de trabajos'!D:D,B27,'Registro de trabajos'!E:E)) | G27: =IF(A27="","",MAX(0,E27-F27)) | H27: =IF(A27="","",SUMIF('Registro de trabajos'!D:D,B27,'Registro de trabajos'!H:H)) | I27: =IF(A27="","",Configuración!B4) | J27: =IF(A27="","",H27-I27) | K27: =IF(A27="","",COUNTIF('Registro de trabajos'!D:D,B27)) | L27: =IF(A27="","",SUMIF('Registro de trabajos'!D:D,B27,'Registro de trabajos'!G:G)) | M27: =IF(A27="","",IF(D27="","EN USO","FINALIZADO"))
A28: =IF('Control de rollos'!D26<>"","B","") | B28: =IF(A28="","",A28&"-"&TEXT(COUNTIF($A$2:A28,A28),"000")) | C28: =IF(A28="","",D26) | E28: =IF(A28="","",Configuración!B3) | F28: =IF(A28="","",SUMIF('Registro de trabajos'!F:F,B28,'Registro de trabajos'!G:G)) | G28: =IF(A28="","",MAX(0,E28-F28)) | H28: =IF(A28="","",0) | I28: =IF(A28="","",0) | J28: =IF(A28="","",H28-I28) | K28: =IF(A28="","",COUNTIF('Registro de trabajos'!F:F,B28)) | L28: =IF(A28="","",F28) | M28: =IF(A28="","",IF(D28="","EN USO","FINALIZADO"))
A29: =IF('Control de rollos'!D26<>"","A","") | B29: =IF(A29="","",A29&"-"&TEXT(COUNTIF($A$2:A29,A29),"000")) | C29: =IF(A29="","",D26) | E29: =IF(A29="","",Configuración!B3) | F29: =IF(A29="","",SUMIF('Registro de trabajos'!D:D,B29,'Registro de trabajos'!E:E)) | G29: =IF(A29="","",MAX(0,E29-F29)) | H29: =IF(A29="","",SUMIF('Registro de trabajos'!D:D,B29,'Registro de trabajos'!H:H)) | I29: =IF(A29="","",Configuración!B4) | J29: =IF(A29="","",H29-I29) | K29: =IF(A29="","",COUNTIF('Registro de trabajos'!D:D,B29)) | L29: =IF(A29="","",SUMIF('Registro de trabajos'!D:D,B29,'Registro de trabajos'!G:G)) | M29: =IF(A29="","",IF(D29="","EN USO","FINALIZADO"))
A30: =IF('Control de rollos'!D28<>"","B","") | B30: =IF(A30="","",A30&"-"&TEXT(COUNTIF($A$2:A30,A30),"000")) | C30: =IF(A30="","",D28) | E30: =IF(A30="","",Configuración!B3) | F30: =IF(A30="","",SUMIF('Registro de trabajos'!F:F,B30,'Registro de trabajos'!G:G)) | G30: =IF(A30="","",MAX(0,E30-F30)) | H30: =IF(A30="","",0) | I30: =IF(A30="","",0) | J30: =IF(A30="","",H30-I30) | K30: =IF(A30="","",COUNTIF('Registro de trabajos'!F:F,B30)) | L30: =IF(A30="","",F30) | M30: =IF(A30="","",IF(D30="","EN USO","FINALIZADO"))
A31: =IF('Control de rollos'!D28<>"","A","") | B31: =IF(A31="","",A31&"-"&TEXT(COUNTIF($A$2:A31,A31),"000")) | C31: =IF(A31="","",D28) | E31: =IF(A31="","",Configuración!B3) | F31: =IF(A31="","",SUMIF('Registro de trabajos'!D:D,B31,'Registro de trabajos'!E:E)) | G31: =IF(A31="","",MAX(0,E31-F31)) | H31: =IF(A31="","",SUMIF('Registro de trabajos'!D:D,B31,'Registro de trabajos'!H:H)) | I31: =IF(A31="","",Configuración!B4) | J31: =IF(A31="","",H31-I31) | K31: =IF(A31="","",COUNTIF('Registro de trabajos'!D:D,B31)) | L31: =IF(A31="","",SUMIF('Registro de trabajos'!D:D,B31,'Registro de trabajos'!G:G)) | M31: =IF(A31="","",IF(D31="","EN USO","FINALIZADO"))
A32: =IF('Control de rollos'!D30<>"","B","") | B32: =IF(A32="","",A32&"-"&TEXT(COUNTIF($A$2:A32,A32),"000")) | C32: =IF(A32="","",D30) | E32: =IF(A32="","",Configuración!B3) | F32: =IF(A32="","",SUMIF('Registro de trabajos'!F:F,B32,'Registro de trabajos'!G:G)) | G32: =IF(A32="","",MAX(0,E32-F32)) | H32: =IF(A32="","",0) | I32: =IF(A32="","",0) | J32: =IF(A32="","",H32-I32) | K32: =IF(A32="","",COUNTIF('Registro de trabajos'!F:F,B32)) | L32: =IF(A32="","",F32) | M32: =IF(A32="","",IF(D32="","EN USO","FINALIZADO"))
A33: =IF('Control de rollos'!D30<>"","A","") | B33: =IF(A33="","",A33&"-"&TEXT(COUNTIF($A$2:A33,A33),"000")) | C33: =IF(A33="","",D30) | E33: =IF(A33="","",Configuración!B3) | F33: =IF(A33="","",SUMIF('Registro de trabajos'!D:D,B33,'Registro de trabajos'!E:E)) | G33: =IF(A33="","",MAX(0,E33-F33)) | H33: =IF(A33="","",SUMIF('Registro de trabajos'!D:D,B33,'Registro de trabajos'!H:H)) | I33: =IF(A33="","",Configuración!B4) | J33: =IF(A33="","",H33-I33) | K33: =IF(A33="","",COUNTIF('Registro de trabajos'!D:D,B33)) | L33: =IF(A33="","",SUMIF('Registro de trabajos'!D:D,B33,'Registro de trabajos'!G:G)) | M33: =IF(A33="","",IF(D33="","EN USO","FINALIZADO"))
A34: =IF('Control de rollos'!D32<>"","B","") | B34: =IF(A34="","",A34&"-"&TEXT(COUNTIF($A$2:A34,A34),"000")) | C34: =IF(A34="","",D32) | E34: =IF(A34="","",Configuración!B3) | F34: =IF(A34="","",SUMIF('Registro de trabajos'!F:F,B34,'Registro de trabajos'!G:G)) | G34: =IF(A34="","",MAX(0,E34-F34)) | H34: =IF(A34="","",0) | I34: =IF(A34="","",0) | J34: =IF(A34="","",H34-I34) | K34: =IF(A34="","",COUNTIF('Registro de trabajos'!F:F,B34)) | L34: =IF(A34="","",F34) | M34: =IF(A34="","",IF(D34="","EN USO","FINALIZADO"))
A35: =IF('Control de rollos'!D32<>"","A","") | B35: =IF(A35="","",A35&"-"&TEXT(COUNTIF($A$2:A35,A35),"000")) | C35: =IF(A35="","",D32) | E35: =IF(A35="","",Configuración!B3) | F35: =IF(A35="","",SUMIF('Registro de trabajos'!D:D,B35,'Registro de trabajos'!E:E)) | G35: =IF(A35="","",MAX(0,E35-F35)) | H35: =IF(A35="","",SUMIF('Registro de trabajos'!D:D,B35,'Registro de trabajos'!H:H)) | I35: =IF(A35="","",Configuración!B4) | J35: =IF(A35="","",H35-I35) | K35: =IF(A35="","",COUNTIF('Registro de trabajos'!D:D,B35)) | L35: =IF(A35="","",SUMIF('Registro de trabajos'!D:D,B35,'Registro de trabajos'!G:G)) | M35: =IF(A35="","",IF(D35="","EN USO","FINALIZADO"))
A36: =IF('Control de rollos'!D34<>"","B","") | B36: =IF(A36="","",A36&"-"&TEXT(COUNTIF($A$2:A36,A36),"000")) | C36: =IF(A36="","",D34) | E36: =IF(A36="","",Configuración!B3) | F36: =IF(A36="","",SUMIF('Registro de trabajos'!F:F,B36,'Registro de trabajos'!G:G)) | G36: =IF(A36="","",MAX(0,E36-F36)) | H36: =IF(A36="","",0) | I36: =IF(A36="","",0) | J36: =IF(A36="","",H36-I36) | K36: =IF(A36="","",COUNTIF('Registro de trabajos'!F:F,B36)) | L36: =IF(A36="","",F36) | M36: =IF(A36="","",IF(D36="","EN USO","FINALIZADO"))
A37: =IF('Control de rollos'!D34<>"","A","") | B37: =IF(A37="","",A37&"-"&TEXT(COUNTIF($A$2:A37,A37),"000")) | C37: =IF(A37="","",D34) | E37: =IF(A37="","",Configuración!B3) | F37: =IF(A37="","",SUMIF('Registro de trabajos'!D:D,B37,'Registro de trabajos'!E:E)) | G37: =IF(A37="","",MAX(0,E37-F37)) | H37: =IF(A37="","",SUMIF('Registro de trabajos'!D:D,B37,'Registro de trabajos'!H:H)) | I37: =IF(A37="","",Configuración!B4) | J37: =IF(A37="","",H37-I37) | K37: =IF(A37="","",COUNTIF('Registro de trabajos'!D:D,B37)) | L37: =IF(A37="","",SUMIF('Registro de trabajos'!D:D,B37,'Registro de trabajos'!G:G)) | M37: =IF(A37="","",IF(D37="","EN USO","FINALIZADO"))
A38: =IF('Control de rollos'!D36<>"","B","") | B38: =IF(A38="","",A38&"-"&TEXT(COUNTIF($A$2:A38,A38),"000")) | C38: =IF(A38="","",D36) | E38: =IF(A38="","",Configuración!B3) | F38: =IF(A38="","",SUMIF('Registro de trabajos'!F:F,B38,'Registro de trabajos'!G:G)) | G38: =IF(A38="","",MAX(0,E38-F38)) | H38: =IF(A38="","",0) | I38: =IF(A38="","",0) | J38: =IF(A38="","",H38-I38) | K38: =IF(A38="","",COUNTIF('Registro de trabajos'!F:F,B38)) | L38: =IF(A38="","",F38) | M38: =IF(A38="","",IF(D38="","EN USO","FINALIZADO"))
A39: =IF('Control de rollos'!D36<>"","A","") | B39: =IF(A39="","",A39&"-"&TEXT(COUNTIF($A$2:A39,A39),"000")) | C39: =IF(A39="","",D36) | E39: =IF(A39="","",Configuración!B3) | F39: =IF(A39="","",SUMIF('Registro de trabajos'!D:D,B39,'Registro de trabajos'!E:E)) | G39: =IF(A39="","",MAX(0,E39-F39)) | H39: =IF(A39="","",SUMIF('Registro de trabajos'!D:D,B39,'Registro de trabajos'!H:H)) | I39: =IF(A39="","",Configuración!B4) | J39: =IF(A39="","",H39-I39) | K39: =IF(A39="","",COUNTIF('Registro de trabajos'!D:D,B39)) | L39: =IF(A39="","",SUMIF('Registro de trabajos'!D:D,B39,'Registro de trabajos'!G:G)) | M39: =IF(A39="","",IF(D39="","EN USO","FINALIZADO"))
A40: =IF('Control de rollos'!D38<>"","B","") | B40: =IF(A40="","",A40&"-"&TEXT(COUNTIF($A$2:A40,A40),"000")) | C40: =IF(A40="","",D38) | E40: =IF(A40="","",Configuración!B3) | F40: =IF(A40="","",SUMIF('Registro de trabajos'!F:F,B40,'Registro de trabajos'!G:G)) | G40: =IF(A40="","",MAX(0,E40-F40)) | H40: =IF(A40="","",0) | I40: =IF(A40="","",0) | J40: =IF(A40="","",H40-I40) | K40: =IF(A40="","",COUNTIF('Registro de trabajos'!F:F,B40)) | L40: =IF(A40="","",F40) | M40: =IF(A40="","",IF(D40="","EN USO","FINALIZADO"))
...

Sheet Configuración
A1: CONFIGURACIÓN UV DTF | F1: IDs de rollo | J1: Rollo A disponible | K1: Rollo B disponible
A2: Parámetro | B2: Valor | C2: Unidad | D2: Nota | F2: A-001 | J2: =IF(AND('Control de rollos'!B2<>"",'Control de rollos'!D2=""),'Control de rollos'!B2,"") -> A-001 | K2: =IF(AND('Control de rollos'!B2<>"",'Control de rollos'!D2=""),IF(LEFT('Control de rollos'!B2,1)="B",'Control de rollos'!B2,""),"")
A3: Metros iniciales por rollo | B3: 100 | C3: m | D3: Cada rollo nuevo parte de 100 m | F3: A-002 | J3: =IF(AND('Control de rollos'!B3<>"",'Control de rollos'!D3=""),'Control de rollos'!B3,"") | K3: =IF(AND('Control de rollos'!B3<>"",'Control de rollos'!D3=""),IF(LEFT('Control de rollos'!B3,1)="B",'Control de rollos'!B3,""),"")
A4: Costo rollo A | B4: 0 | C4: S/ | D4: Ingresar costo real | F4: A-003 | J4: =IF(AND('Control de rollos'!B4<>"",'Control de rollos'!D4=""),'Control de rollos'!B4,"") -> B-002 | K4: =IF(AND('Control de rollos'!B4<>"",'Control de rollos'!D4=""),IF(LEFT('Control de rollos'!B4,1)="B",'Control de rollos'!B4,""),"") -> B-002
A5: Costo rollo B | B5: 0 | C5: S/ | D5: Ingresar costo real | F5: A-004 | J5: =IF(AND('Control de rollos'!B5<>"",'Control de rollos'!D5=""),'Control de rollos'!B5,"") | K5: =IF(AND('Control de rollos'!B5<>"",'Control de rollos'!D5=""),IF(LEFT('Control de rollos'!B5,1)="B",'Control de rollos'!B5,""),"")
A6: Fecha actual | B6: 46272 | D6: Rollo A nuevo desde esta fecha | F6: A-005 | J6: =IF(AND('Control de rollos'!B6<>"",'Control de rollos'!D6=""),'Control de rollos'!B6,"") | K6: =IF(AND('Control de rollos'!B6<>"",'Control de rollos'!D6=""),IF(LEFT('Control de rollos'!B6,1)="B",'Control de rollos'!B6,""),"")
F7: A-006 | J7: =IF(AND('Control de rollos'!B7<>"",'Control de rollos'!D7=""),'Control de rollos'!B7,"") | K7: =IF(AND('Control de rollos'!B7<>"",'Control de rollos'!D7=""),IF(LEFT('Control de rollos'!B7,1)="B",'Control de rollos'!B7,""),"")
F8: A-007 | J8: =IF(AND('Control de rollos'!B8<>"",'Control de rollos'!D8=""),'Control de rollos'!B8,"") | K8: =IF(AND('Control de rollos'!B8<>"",'Control de rollos'!D8=""),IF(LEFT('Control de rollos'!B8,1)="B",'Control de rollos'!B8,""),"")
F9: A-008 | J9: =IF(AND('Control de rollos'!B9<>"",'Control de rollos'!D9=""),'Control de rollos'!B9,"") | K9: =IF(AND('Control de rollos'!B9<>"",'Control de rollos'!D9=""),IF(LEFT('Control de rollos'!B9,1)="B",'Control de rollos'!B9,""),"")
F10: A-009 | J10: =IF(AND('Control de rollos'!B10<>"",'Control de rollos'!D10=""),'Control de rollos'!B10,"") | K10: =IF(AND('Control de rollos'!B10<>"",'Control de rollos'!D10=""),IF(LEFT('Control de rollos'!B10,1)="B",'Control de rollos'!B10,""),"")
F11: A-010 | J11: =IF(AND('Control de rollos'!B11<>"",'Control de rollos'!D11=""),'Control de rollos'!B11,"") | K11: =IF(AND('Control de rollos'!B11<>"",'Control de rollos'!D11=""),IF(LEFT('Control de rollos'!B11,1)="B",'Control de rollos'!B11,""),"")
F12: B-001 | J12: =IF(AND('Control de rollos'!B12<>"",'Control de rollos'!D12=""),'Control de rollos'!B12,"") | K12: =IF(AND('Control de rollos'!B12<>"",'Control de rollos'!D12=""),IF(LEFT('Control de rollos'!B12,1)="B",'Control de rollos'!B12,""),"")
F13: B-002 | J13: =IF(AND('Control de rollos'!B13<>"",'Control de rollos'!D13=""),'Control de rollos'!B13,"") | K13: =IF(AND('Control de rollos'!B13<>"",'Control de rollos'!D13=""),IF(LEFT('Control de rollos'!B13,1)="B",'Control de rollos'!B13,""),"")
F14: B-003 | J14: =IF(AND('Control de rollos'!B14<>"",'Control de rollos'!D14=""),'Control de rollos'!B14,"") | K14: =IF(AND('Control de rollos'!B14<>"",'Control de rollos'!D14=""),IF(LEFT('Control de rollos'!B14,1)="B",'Control de rollos'!B14,""),"")
F15: B-004 | J15: =IF(AND('Control de rollos'!B15<>"",'Control de rollos'!D15=""),'Control de rollos'!B15,"") | K15: =IF(AND('Control de rollos'!B15<>"",'Control de rollos'!D15=""),IF(LEFT('Control de rollos'!B15,1)="B",'Control de rollos'!B15,""),"")
F16: B-005 | J16: =IF(AND('Control de rollos'!B16<>"",'Control de rollos'!D16=""),'Control de rollos'!B16,"") | K16: =IF(AND('Control de rollos'!B16<>"",'Control de rollos'!D16=""),IF(LEFT('Control de rollos'!B16,1)="B",'Control de rollos'!B16,""),"")
F17: B-006 | J17: =IF(AND('Control de rollos'!B17<>"",'Control de rollos'!D17=""),'Control de rollos'!B17,"") | K17: =IF(AND('Control de rollos'!B17<>"",'Control de rollos'!D17=""),IF(LEFT('Control de rollos'!B17,1)="B",'Control de rollos'!B17,""),"")
F18: B-007 | J18: =IF(AND('Control de rollos'!B18<>"",'Control de rollos'!D18=""),'Control de rollos'!B18,"") | K18: =IF(AND('Control de rollos'!B18<>"",'Control de rollos'!D18=""),IF(LEFT('Control de rollos'!B18,1)="B",'Control de rollos'!B18,""),"")
... F21: B-010 | J21: =IF(AND('Control de rollos'!B21<>"",'Control de rollos'!D21=""),'Control de rollos'!B21,"") | K21: =IF(AND('Control de rollos'!B21<>"",'Control de rollos'!D21=""),IF(LEFT('Control de rollos'!B21,1)="B",'Control de rollos'!B21,""),"")
J22: =IF(AND('Control de rollos'!B22<>"",'Control de rollos'!D22=""),'Control de rollos'!B22,"") | K22: =IF(AND('Control de rollos'!B22<>"",'Control de rollos'!D22=""),IF(LEFT('Control de rollos'!B22,1)="B",'Control de rollos'!B22,""),"")
J23: =IF(AND('Control de rollos'!B23<>"",'Control de rollos'!D23=""),'Control de rollos'!B23,"") | K23: =IF(AND('Control de rollos'!B23<>"",'Control de rollos'!D23=""),IF(LEFT('Control de rollos'!B23,1)="B",'Control de rollos'!B23,""),"")
J24: =IF(AND('Control de rollos'!B24<>"",'Control de rollos'!D24=""),'Control de rollos'!B24,"") | K24: =IF(AND('Control de rollos'!B24<>"",'Control de rollos'!D24=""),IF(LEFT('Control de rollos'!B24,1)="B",'Control de rollos'!B24,""),"")
J25: =IF(AND('Control de rollos'!B25<>"",'Control de rollos'!D25=""),'Control de rollos'!B25,"") | K25: =IF(AND('Control de rollos'!B25<>"",'Control de rollos'!D25=""),IF(LEFT('Control de rollos'!B25,1)="B",'Control de rollos'!B25,""),"")
J26: =IF(AND('Control de rollos'!B26<>"",'Control de rollos'!D26=""),'Control de rollos'!B26,"") | K26: =IF(AND('Control de rollos'!B26<>"",'Control de rollos'!D26=""),IF(LEFT('Control de rollos'!B26,1)="B",'Control de rollos'!B26,""),"")
J27: =IF(AND('Control de rollos'!B27<>"",'Control de rollos'!D27=""),'Control de rollos'!B27,"") | K27: =IF(AND('Control de rollos'!B27<>"",'Control de rollos'!D27=""),IF(LEFT('Control de rollos'!B27,1)="B",'Control de rollos'!B27,""),"")
J28: =IF(AND('Control de rollos'!B28<>"",'Control de rollos'!D28=""),'Control de rollos'!B28,"") | K28: =IF(AND('Control de rollos'!B28<>"",'Control de rollos'!D28=""),IF(LEFT('Control de rollos'!B28,1)="B",'Control de rollos'!B28,""),"")
J29: =IF(AND('Control de rollos'!B29<>"",'Control de rollos'!D29=""),'Control de rollos'!B29,"") | K29: =IF(AND('Control de rollos'!B29<>"",'Control de rollos'!D29=""),IF(LEFT('Control de rollos'!B29,1)="B",'Control de rollos'!B29,""),"")
J30: =IF(AND('Control de rollos'!B30<>"",'Control de rollos'!D30=""),'Control de rollos'!B30,"") | K30: =IF(AND('Control de rollos'!B30<>"",'Control de rollos'!D30=""),IF(LEFT('Control de rollos'!B30,1)="B",'Control de rollos'!B30,""),"")
J31: =IF(AND('Control de rollos'!B31<>"",'Control de rollos'!D31=""),'Control de rollos'!B31,"") | K31: =IF(AND('Control de rollos'!B31<>"",'Control de rollos'!D31=""),IF(LEFT('Control de rollos'!B31,1)="B",'Control de rollos'!B31,""),"")
J32: =IF(AND('Control de rollos'!B32<>"",'Control de rollos'!D32=""),'Control de rollos'!B32,"") | K32: =IF(AND('Control de rollos'!B32<>"",'Control de rollos'!D32=""),IF(LEFT('Control de rollos'!B32,1)="B",'Control de rollos'!B32,""),"")
J33: =IF(AND('Control de rollos'!B33<>"",'Control de rollos'!D33=""),'Control de rollos'!B33,"") | K33: =IF(AND('Control de rollos'!B33<>"",'Control de rollos'!D33=""),IF(LEFT('Control de rollos'!B33,1)="B",'Control de rollos'!B33,""),"")
... J101: =IF(AND('Control de rollos'!B101<>"",'Control de rollos'!D101=""),'Control de rollos'!B101,"") | K101: =IF(AND('Control de rollos'!B101<>"",'Control de rollos'!D101=""),IF(LEFT('Control de rollos'!B101,1)="B",'Control de rollos'!B101,""),"")
